(0.002) QUERY = "\n            SELECT name, type FROM sqlite_master\n            WHERE type in ('table', 'view') AND NOT name='sqlite_sequence'\n            ORDER BY name" - PARAMS = (); args=None
(0.000) QUERY = 'SELECT "django_migrations"."app", "django_migrations"."name" FROM "django_migrations"' - PARAMS = (); args=()
Internal Server Error: /newrandom
Traceback (most recent call last):
  File "/usr/lib64/python3.4/site-packages/django/core/urlresolvers.py", line 190, in regex
    compiled_regex = re.compile(regex, re.UNICODE)
  File "/usr/lib64/python3.4/re.py", line 223, in compile
    return _compile(pattern, flags)
  File "/usr/lib64/python3.4/re.py", line 294, in _compile
    p = sre_compile.compile(pattern, flags)
  File "/usr/lib64/python3.4/sre_compile.py", line 568, in compile
    p = sre_parse.parse(p, flags)
  File "/usr/lib64/python3.4/sre_parse.py", line 780, in parse
    p = _parse_sub(source, pattern, 0)
  File "/usr/lib64/python3.4/sre_parse.py", line 377, in _parse_sub
    itemsappend(_parse(source, state))
  File "/usr/lib64/python3.4/sre_parse.py", line 586, in _parse
    raise error("nothing to repeat")
sre_constants.error: nothing to repeat

During handling of the above exception, another exception occurred:

Traceback (most recent call last):
  File "/usr/lib64/python3.4/site-packages/django/core/handlers/base.py", line 108, in get_response
    response = middleware_method(request)
  File "/usr/lib64/python3.4/site-packages/django/middleware/common.py", line 74, in process_request
    if (not urlresolvers.is_valid_path(request.path_info, urlconf) and
  File "/usr/lib64/python3.4/site-packages/django/core/urlresolvers.py", line 646, in is_valid_path
    resolve(path, urlconf)
  File "/usr/lib64/python3.4/site-packages/django/core/urlresolvers.py", line 521, in resolve
    return get_resolver(urlconf).resolve(path)
  File "/usr/lib64/python3.4/site-packages/django/core/urlresolvers.py", line 367, in resolve
    sub_match = pattern.resolve(new_path)
  File "/usr/lib64/python3.4/site-packages/django/core/urlresolvers.py", line 226, in resolve
    match = self.regex.search(path)
  File "/usr/lib64/python3.4/site-packages/django/core/urlresolvers.py", line 194, in regex
    (regex, six.text_type(e)))
django.core.exceptions.ImproperlyConfigured: "*/newrandom/$" is not a valid regular expression: nothing to repeat
(0.000) QUERY = "\n            SELECT name, type FROM sqlite_master\n            WHERE type in ('table', 'view') AND NOT name='sqlite_sequence'\n            ORDER BY name" - PARAMS = (); args=None
(0.000) QUERY = 'SELECT "django_migrations"."app", "django_migrations"."name" FROM "django_migrations"' - PARAMS = (); args=()
Not Found: /newrandom
(0.001) QUERY = "\n            SELECT name, type FROM sqlite_master\n            WHERE type in ('table', 'view') AND NOT name='sqlite_sequence'\n            ORDER BY name" - PARAMS = (); args=None
(0.000) QUERY = 'SELECT "django_migrations"."app", "django_migrations"."name" FROM "django_migrations"' - PARAMS = (); args=()
Internal Server Error: /newrandom
Traceback (most recent call last):
  File "/usr/lib64/python3.4/site-packages/django/core/handlers/base.py", line 108, in get_response
    response = middleware_method(request)
  File "/usr/lib64/python3.4/site-packages/django/middleware/common.py", line 75, in process_request
    urlresolvers.is_valid_path("%s/" % request.path_info, urlconf)):
  File "/usr/lib64/python3.4/site-packages/django/core/urlresolvers.py", line 646, in is_valid_path
    resolve(path, urlconf)
  File "/usr/lib64/python3.4/site-packages/django/core/urlresolvers.py", line 521, in resolve
    return get_resolver(urlconf).resolve(path)
  File "/usr/lib64/python3.4/site-packages/django/core/urlresolvers.py", line 367, in resolve
    sub_match = pattern.resolve(new_path)
  File "/usr/lib64/python3.4/site-packages/django/core/urlresolvers.py", line 239, in resolve
    return ResolverMatch(self.callback, args, kwargs, self.name)
  File "/usr/lib64/python3.4/site-packages/django/core/urlresolvers.py", line 246, in callback
    self._callback = get_callable(self._callback_str)
  File "/usr/lib64/python3.4/functools.py", line 448, in wrapper
    result = user_function(*args, **kwds)
  File "/usr/lib64/python3.4/site-packages/django/core/urlresolvers.py", line 95, in get_callable
    mod_name, func_name = get_mod_func(lookup_view)
  File "/usr/lib64/python3.4/site-packages/django/core/urlresolvers.py", line 158, in get_mod_func
    dot = callback.rindex('.')
AttributeError: 'JsonResponse' object has no attribute 'rindex'
(0.000) QUERY = "\n            SELECT name, type FROM sqlite_master\n            WHERE type in ('table', 'view') AND NOT name='sqlite_sequence'\n            ORDER BY name" - PARAMS = (); args=None
(0.000) QUERY = 'SELECT "django_migrations"."app", "django_migrations"."name" FROM "django_migrations"' - PARAMS = (); args=()
Internal Server Error: /newrandom
Traceback (most recent call last):
  File "/usr/lib64/python3.4/site-packages/django/core/handlers/base.py", line 108, in get_response
    response = middleware_method(request)
  File "/usr/lib64/python3.4/site-packages/django/middleware/common.py", line 84, in process_request
    "settings.") % (new_url[0], new_url[1]))
RuntimeError: You called this URL via POST, but the URL doesn't end in a slash and you have APPEND_SLASH set. Django can't redirect to the slash URL while maintaining POST data. Change your form to point to 127.0.0.1:8000/newrandom/ (note the trailing slash), or set APPEND_SLASH=False in your Django settings.
Forbidden (CSRF cookie not set.): /newrandom/
(0.000) QUERY = "\n            SELECT name, type FROM sqlite_master\n            WHERE type in ('table', 'view') AND NOT name='sqlite_sequence'\n            ORDER BY name" - PARAMS = (); args=None
(0.000) QUERY = 'SELECT "django_migrations"."app", "django_migrations"."name" FROM "django_migrations"' - PARAMS = (); args=()
Internal Server Error: /greeting/
Traceback (most recent call last):
  File "/usr/lib64/python3.4/site-packages/django/core/handlers/base.py", line 132, in get_response
    response = wrapped_callback(request, *callback_args, **callback_kwargs)
  File "/root/django/first/mysite/mysite/views.py", line 24, in greeting
    return render_to_response('/static/app/quotes/index.html')
  File "/usr/lib64/python3.4/site-packages/django/shortcuts.py", line 39, in render_to_response
    content = loader.render_to_string(template_name, context, using=using)
  File "/usr/lib64/python3.4/site-packages/django/template/loader.py", line 98, in render_to_string
    template = get_template(template_name, using=using)
  File "/usr/lib64/python3.4/site-packages/django/template/loader.py", line 46, in get_template
    raise TemplateDoesNotExist(template_name)
django.template.base.TemplateDoesNotExist: /static/app/quotes/index.html
(0.000) QUERY = "\n            SELECT name, type FROM sqlite_master\n            WHERE type in ('table', 'view') AND NOT name='sqlite_sequence'\n            ORDER BY name" - PARAMS = (); args=None
(0.000) QUERY = 'SELECT "django_migrations"."app", "django_migrations"."name" FROM "django_migrations"' - PARAMS = (); args=()
Internal Server Error: /greeting/
Traceback (most recent call last):
  File "/usr/lib64/python3.4/site-packages/django/core/handlers/base.py", line 132, in get_response
    response = wrapped_callback(request, *callback_args, **callback_kwargs)
  File "/root/django/first/mysite/mysite/views.py", line 24, in greeting
    return render_to_response('../static/app/quotes/index.html')
  File "/usr/lib64/python3.4/site-packages/django/shortcuts.py", line 39, in render_to_response
    content = loader.render_to_string(template_name, context, using=using)
  File "/usr/lib64/python3.4/site-packages/django/template/loader.py", line 98, in render_to_string
    template = get_template(template_name, using=using)
  File "/usr/lib64/python3.4/site-packages/django/template/loader.py", line 46, in get_template
    raise TemplateDoesNotExist(template_name)
django.template.base.TemplateDoesNotExist: ../static/app/quotes/index.html
(0.000) QUERY = "\n            SELECT name, type FROM sqlite_master\n            WHERE type in ('table', 'view') AND NOT name='sqlite_sequence'\n            ORDER BY name" - PARAMS = (); args=None
(0.000) QUERY = 'SELECT "django_migrations"."app", "django_migrations"."name" FROM "django_migrations"' - PARAMS = (); args=()
Internal Server Error: /greeting/
Traceback (most recent call last):
  File "/usr/lib64/python3.4/site-packages/django/core/handlers/base.py", line 132, in get_response
    response = wrapped_callback(request, *callback_args, **callback_kwargs)
  File "/root/django/first/mysite/mysite/views.py", line 24, in greeting
    return render_to_response('/root/django/first/mysite/mysite/static/app/quotes/index.html')
  File "/usr/lib64/python3.4/site-packages/django/shortcuts.py", line 39, in render_to_response
    content = loader.render_to_string(template_name, context, using=using)
  File "/usr/lib64/python3.4/site-packages/django/template/loader.py", line 98, in render_to_string
    template = get_template(template_name, using=using)
  File "/usr/lib64/python3.4/site-packages/django/template/loader.py", line 46, in get_template
    raise TemplateDoesNotExist(template_name)
django.template.base.TemplateDoesNotExist: /root/django/first/mysite/mysite/static/app/quotes/index.html
(0.000) QUERY = "\n            SELECT name, type FROM sqlite_master\n            WHERE type in ('table', 'view') AND NOT name='sqlite_sequence'\n            ORDER BY name" - PARAMS = (); args=None
(0.000) QUERY = 'SELECT "django_migrations"."app", "django_migrations"."name" FROM "django_migrations"' - PARAMS = (); args=()
Internal Server Error: /greeting/
Traceback (most recent call last):
  File "/usr/lib64/python3.4/site-packages/django/core/handlers/base.py", line 132, in get_response
    response = wrapped_callback(request, *callback_args, **callback_kwargs)
  File "/root/django/first/mysite/mysite/views.py", line 24, in greeting
    return render_to_response('static/app/quotes/index.html')
  File "/usr/lib64/python3.4/site-packages/django/shortcuts.py", line 39, in render_to_response
    content = loader.render_to_string(template_name, context, using=using)
  File "/usr/lib64/python3.4/site-packages/django/template/loader.py", line 98, in render_to_string
    template = get_template(template_name, using=using)
  File "/usr/lib64/python3.4/site-packages/django/template/loader.py", line 46, in get_template
    raise TemplateDoesNotExist(template_name)
django.template.base.TemplateDoesNotExist: static/app/quotes/index.html
(0.000) QUERY = "\n            SELECT name, type FROM sqlite_master\n            WHERE type in ('table', 'view') AND NOT name='sqlite_sequence'\n            ORDER BY name" - PARAMS = (); args=None
(0.000) QUERY = 'SELECT "django_migrations"."app", "django_migrations"."name" FROM "django_migrations"' - PARAMS = (); args=()
(0.000) QUERY = "\n            SELECT name, type FROM sqlite_master\n            WHERE type in ('table', 'view') AND NOT name='sqlite_sequence'\n            ORDER BY name" - PARAMS = (); args=None
(0.000) QUERY = 'SELECT "django_migrations"."app", "django_migrations"."name" FROM "django_migrations"' - PARAMS = (); args=()
Internal Server Error: /greeting/
Traceback (most recent call last):
  File "/usr/lib64/python3.4/site-packages/django/core/handlers/base.py", line 132, in get_response
    response = wrapped_callback(request, *callback_args, **callback_kwargs)
  File "/root/django/first/mysite/mysite/views.py", line 24, in greeting
    return render_to_response('static/app/quotes/index.html')
  File "/usr/lib64/python3.4/site-packages/django/shortcuts.py", line 39, in render_to_response
    content = loader.render_to_string(template_name, context, using=using)
  File "/usr/lib64/python3.4/site-packages/django/template/loader.py", line 98, in render_to_string
    template = get_template(template_name, using=using)
  File "/usr/lib64/python3.4/site-packages/django/template/loader.py", line 46, in get_template
    raise TemplateDoesNotExist(template_name)
django.template.base.TemplateDoesNotExist: static/app/quotes/index.html
(0.000) QUERY = "\n            SELECT name, type FROM sqlite_master\n            WHERE type in ('table', 'view') AND NOT name='sqlite_sequence'\n            ORDER BY name" - PARAMS = (); args=None
(0.000) QUERY = 'SELECT "django_migrations"."app", "django_migrations"."name" FROM "django_migrations"' - PARAMS = (); args=()
(0.000) QUERY = "\n            SELECT name, type FROM sqlite_master\n            WHERE type in ('table', 'view') AND NOT name='sqlite_sequence'\n            ORDER BY name" - PARAMS = (); args=None
(0.000) QUERY = 'SELECT "django_migrations"."app", "django_migrations"."name" FROM "django_migrations"' - PARAMS = (); args=()
Internal Server Error: /greeting/
Traceback (most recent call last):
  File "/usr/lib64/python3.4/site-packages/django/core/handlers/base.py", line 132, in get_response
    response = wrapped_callback(request, *callback_args, **callback_kwargs)
  File "/root/django/first/mysite/mysite/views.py", line 24, in greeting
    return render_to_response('testdir/quotes/index.html')
  File "/usr/lib64/python3.4/site-packages/django/shortcuts.py", line 39, in render_to_response
    content = loader.render_to_string(template_name, context, using=using)
  File "/usr/lib64/python3.4/site-packages/django/template/loader.py", line 98, in render_to_string
    template = get_template(template_name, using=using)
  File "/usr/lib64/python3.4/site-packages/django/template/loader.py", line 46, in get_template
    raise TemplateDoesNotExist(template_name)
django.template.base.TemplateDoesNotExist: testdir/quotes/index.html
(0.000) QUERY = "\n            SELECT name, type FROM sqlite_master\n            WHERE type in ('table', 'view') AND NOT name='sqlite_sequence'\n            ORDER BY name" - PARAMS = (); args=None
(0.000) QUERY = 'SELECT "django_migrations"."app", "django_migrations"."name" FROM "django_migrations"' - PARAMS = (); args=()
Internal Server Error: /greeting/
Traceback (most recent call last):
  File "/usr/lib64/python3.4/site-packages/django/core/handlers/base.py", line 132, in get_response
    response = wrapped_callback(request, *callback_args, **callback_kwargs)
  File "/root/django/first/mysite/mysite/views.py", line 24, in greeting
    return render_to_response('testdir/app/quotes/index.html')
  File "/usr/lib64/python3.4/site-packages/django/shortcuts.py", line 39, in render_to_response
    content = loader.render_to_string(template_name, context, using=using)
  File "/usr/lib64/python3.4/site-packages/django/template/loader.py", line 98, in render_to_string
    template = get_template(template_name, using=using)
  File "/usr/lib64/python3.4/site-packages/django/template/loader.py", line 46, in get_template
    raise TemplateDoesNotExist(template_name)
django.template.base.TemplateDoesNotExist: testdir/app/quotes/index.html
(0.000) QUERY = "\n            SELECT name, type FROM sqlite_master\n            WHERE type in ('table', 'view') AND NOT name='sqlite_sequence'\n            ORDER BY name" - PARAMS = (); args=None
(0.000) QUERY = 'SELECT "django_migrations"."app", "django_migrations"."name" FROM "django_migrations"' - PARAMS = (); args=()
(0.000) QUERY = "\n            SELECT name, type FROM sqlite_master\n            WHERE type in ('table', 'view') AND NOT name='sqlite_sequence'\n            ORDER BY name" - PARAMS = (); args=None
(0.000) QUERY = 'SELECT "django_migrations"."app", "django_migrations"."name" FROM "django_migrations"' - PARAMS = (); args=()
Internal Server Error: /greeting/
Traceback (most recent call last):
  File "/usr/lib64/python3.4/site-packages/django/core/handlers/base.py", line 132, in get_response
    response = wrapped_callback(request, *callback_args, **callback_kwargs)
  File "/root/django/first/mysite/mysite/views.py", line 24, in greeting
    return render_to_response('testdir/quotes/index.html')
  File "/usr/lib64/python3.4/site-packages/django/shortcuts.py", line 39, in render_to_response
    content = loader.render_to_string(template_name, context, using=using)
  File "/usr/lib64/python3.4/site-packages/django/template/loader.py", line 98, in render_to_string
    template = get_template(template_name, using=using)
  File "/usr/lib64/python3.4/site-packages/django/template/loader.py", line 46, in get_template
    raise TemplateDoesNotExist(template_name)
django.template.base.TemplateDoesNotExist: testdir/quotes/index.html
(0.000) QUERY = "\n            SELECT name, type FROM sqlite_master\n            WHERE type in ('table', 'view') AND NOT name='sqlite_sequence'\n            ORDER BY name" - PARAMS = (); args=None
(0.000) QUERY = 'SELECT "django_migrations"."app", "django_migrations"."name" FROM "django_migrations"' - PARAMS = (); args=()
Internal Server Error: /greeting/
Traceback (most recent call last):
  File "/usr/lib64/python3.4/site-packages/django/core/handlers/base.py", line 132, in get_response
    response = wrapped_callback(request, *callback_args, **callback_kwargs)
  File "/root/django/first/mysite/mysite/views.py", line 24, in greeting
    return render_to_response('app/quotes/index.html')
  File "/usr/lib64/python3.4/site-packages/django/shortcuts.py", line 39, in render_to_response
    content = loader.render_to_string(template_name, context, using=using)
  File "/usr/lib64/python3.4/site-packages/django/template/loader.py", line 98, in render_to_string
    template = get_template(template_name, using=using)
  File "/usr/lib64/python3.4/site-packages/django/template/loader.py", line 46, in get_template
    raise TemplateDoesNotExist(template_name)
django.template.base.TemplateDoesNotExist: app/quotes/index.html
(0.003) QUERY = "\n            SELECT name, type FROM sqlite_master\n            WHERE type in ('table', 'view') AND NOT name='sqlite_sequence'\n            ORDER BY name" - PARAMS = (); args=None
(0.001) QUERY = 'SELECT "django_migrations"."app", "django_migrations"."name" FROM "django_migrations"' - PARAMS = (); args=()
(0.001) QUERY = "\n            SELECT name, type FROM sqlite_master\n            WHERE type in ('table', 'view') AND NOT name='sqlite_sequence'\n            ORDER BY name" - PARAMS = (); args=None
(0.000) QUERY = 'SELECT "django_migrations"."app", "django_migrations"."name" FROM "django_migrations"' - PARAMS = (); args=()
(0.000) QUERY = "\n            SELECT name, type FROM sqlite_master\n            WHERE type in ('table', 'view') AND NOT name='sqlite_sequence'\n            ORDER BY name" - PARAMS = (); args=None
(0.000) QUERY = 'SELECT "django_migrations"."app", "django_migrations"."name" FROM "django_migrations"' - PARAMS = (); args=()
Internal Server Error: /greeting/
Traceback (most recent call last):
  File "/usr/lib64/python3.4/site-packages/django/core/handlers/base.py", line 132, in get_response
    response = wrapped_callback(request, *callback_args, **callback_kwargs)
  File "/root/django/first/mysite/mysite/views.py", line 24, in greeting
    return render_to_response('testdir/quotes/index.html')
  File "/usr/lib64/python3.4/site-packages/django/shortcuts.py", line 39, in render_to_response
    content = loader.render_to_string(template_name, context, using=using)
  File "/usr/lib64/python3.4/site-packages/django/template/loader.py", line 98, in render_to_string
    template = get_template(template_name, using=using)
  File "/usr/lib64/python3.4/site-packages/django/template/loader.py", line 46, in get_template
    raise TemplateDoesNotExist(template_name)
django.template.base.TemplateDoesNotExist: testdir/quotes/index.html
(0.000) QUERY = "\n            SELECT name, type FROM sqlite_master\n            WHERE type in ('table', 'view') AND NOT name='sqlite_sequence'\n            ORDER BY name" - PARAMS = (); args=None
(0.005) QUERY = 'SELECT "django_migrations"."app", "django_migrations"."name" FROM "django_migrations"' - PARAMS = (); args=()
(0.000) QUERY = "\n            SELECT name, type FROM sqlite_master\n            WHERE type in ('table', 'view') AND NOT name='sqlite_sequence'\n            ORDER BY name" - PARAMS = (); args=None
(0.000) QUERY = 'SELECT "django_migrations"."app", "django_migrations"."name" FROM "django_migrations"' - PARAMS = (); args=()
Not Found: /app/quotes/index.html
(0.000) QUERY = "\n            SELECT name, type FROM sqlite_master\n            WHERE type in ('table', 'view') AND NOT name='sqlite_sequence'\n            ORDER BY name" - PARAMS = (); args=None
(0.000) QUERY = 'SELECT "django_migrations"."app", "django_migrations"."name" FROM "django_migrations"' - PARAMS = (); args=()
(0.000) QUERY = "\n            SELECT name, type FROM sqlite_master\n            WHERE type in ('table', 'view') AND NOT name='sqlite_sequence'\n            ORDER BY name" - PARAMS = (); args=None
(0.000) QUERY = 'SELECT "django_migrations"."app", "django_migrations"."name" FROM "django_migrations"' - PARAMS = (); args=()
(0.000) QUERY = "\n            SELECT name, type FROM sqlite_master\n            WHERE type in ('table', 'view') AND NOT name='sqlite_sequence'\n            ORDER BY name" - PARAMS = (); args=None
(0.000) QUERY = 'SELECT "django_migrations"."app", "django_migrations"."name" FROM "django_migrations"' - PARAMS = (); args=()
(0.022) QUERY = "\n            SELECT name, type FROM sqlite_master\n            WHERE type in ('table', 'view') AND NOT name='sqlite_sequence'\n            ORDER BY name" - PARAMS = (); args=None
(0.000) QUERY = 'SELECT "django_migrations"."app", "django_migrations"."name" FROM "django_migrations"' - PARAMS = (); args=()
Internal Server Error: /favicon.ico
Traceback (most recent call last):
  File "/usr/lib64/python3.4/site-packages/django/core/urlresolvers.py", line 393, in urlconf_module
    return self._urlconf_module
AttributeError: 'RegexURLResolver' object has no attribute '_urlconf_module'

During handling of the above exception, another exception occurred:

Traceback (most recent call last):
  File "/usr/lib64/python3.4/site-packages/django/core/handlers/base.py", line 108, in get_response
    response = middleware_method(request)
  File "/usr/lib64/python3.4/site-packages/django/middleware/common.py", line 74, in process_request
    if (not urlresolvers.is_valid_path(request.path_info, urlconf) and
  File "/usr/lib64/python3.4/site-packages/django/core/urlresolvers.py", line 646, in is_valid_path
    resolve(path, urlconf)
  File "/usr/lib64/python3.4/site-packages/django/core/urlresolvers.py", line 521, in resolve
    return get_resolver(urlconf).resolve(path)
  File "/usr/lib64/python3.4/site-packages/django/core/urlresolvers.py", line 365, in resolve
    for pattern in self.url_patterns:
  File "/usr/lib64/python3.4/site-packages/django/core/urlresolvers.py", line 401, in url_patterns
    patterns = getattr(self.urlconf_module, "urlpatterns", self.urlconf_module)
  File "/usr/lib64/python3.4/site-packages/django/core/urlresolvers.py", line 395, in urlconf_module
    self._urlconf_module = import_module(self.urlconf_name)
  File "/usr/lib64/python3.4/importlib/__init__.py", line 109, in import_module
    return _bootstrap._gcd_import(name[level:], package, level)
  File "<frozen importlib._bootstrap>", line 2254, in _gcd_import
  File "<frozen importlib._bootstrap>", line 2237, in _find_and_load
  File "<frozen importlib._bootstrap>", line 2226, in _find_and_load_unlocked
  File "<frozen importlib._bootstrap>", line 1200, in _load_unlocked
  File "<frozen importlib._bootstrap>", line 1129, in _exec
  File "<frozen importlib._bootstrap>", line 1467, in exec_module
  File "<frozen importlib._bootstrap>", line 1572, in get_code
  File "<frozen importlib._bootstrap>", line 1532, in source_to_code
  File "<frozen importlib._bootstrap>", line 321, in _call_with_frames_removed
  File "/root/django/first/mysite/mysite/urls.py", line 29
    url(r'newtpb/$', respond_with_tpb_quote)
      ^
SyntaxError: invalid syntax
Internal Server Error: /favicon.ico
Traceback (most recent call last):
  File "/usr/lib64/python3.4/site-packages/django/core/urlresolvers.py", line 393, in urlconf_module
    return self._urlconf_module
AttributeError: 'RegexURLResolver' object has no attribute '_urlconf_module'

During handling of the above exception, another exception occurred:

Traceback (most recent call last):
  File "/usr/lib64/python3.4/site-packages/django/core/handlers/base.py", line 108, in get_response
    response = middleware_method(request)
  File "/usr/lib64/python3.4/site-packages/django/middleware/common.py", line 74, in process_request
    if (not urlresolvers.is_valid_path(request.path_info, urlconf) and
  File "/usr/lib64/python3.4/site-packages/django/core/urlresolvers.py", line 646, in is_valid_path
    resolve(path, urlconf)
  File "/usr/lib64/python3.4/site-packages/django/core/urlresolvers.py", line 521, in resolve
    return get_resolver(urlconf).resolve(path)
  File "/usr/lib64/python3.4/site-packages/django/core/urlresolvers.py", line 365, in resolve
    for pattern in self.url_patterns:
  File "/usr/lib64/python3.4/site-packages/django/core/urlresolvers.py", line 401, in url_patterns
    patterns = getattr(self.urlconf_module, "urlpatterns", self.urlconf_module)
  File "/usr/lib64/python3.4/site-packages/django/core/urlresolvers.py", line 395, in urlconf_module
    self._urlconf_module = import_module(self.urlconf_name)
  File "/usr/lib64/python3.4/importlib/__init__.py", line 109, in import_module
    return _bootstrap._gcd_import(name[level:], package, level)
  File "<frozen importlib._bootstrap>", line 2254, in _gcd_import
  File "<frozen importlib._bootstrap>", line 2237, in _find_and_load
  File "<frozen importlib._bootstrap>", line 2226, in _find_and_load_unlocked
  File "<frozen importlib._bootstrap>", line 1200, in _load_unlocked
  File "<frozen importlib._bootstrap>", line 1129, in _exec
  File "<frozen importlib._bootstrap>", line 1467, in exec_module
  File "<frozen importlib._bootstrap>", line 1572, in get_code
  File "<frozen importlib._bootstrap>", line 1532, in source_to_code
  File "<frozen importlib._bootstrap>", line 321, in _call_with_frames_removed
  File "/root/django/first/mysite/mysite/urls.py", line 29
    url(r'newtpb/$', respond_with_tpb_quote)
      ^
SyntaxError: invalid syntax
Internal Server Error: /newtpb/
Traceback (most recent call last):
  File "/usr/lib64/python3.4/site-packages/django/core/urlresolvers.py", line 393, in urlconf_module
    return self._urlconf_module
AttributeError: 'RegexURLResolver' object has no attribute '_urlconf_module'

During handling of the above exception, another exception occurred:

Traceback (most recent call last):
  File "/usr/lib64/python3.4/site-packages/django/core/handlers/base.py", line 119, in get_response
    resolver_match = resolver.resolve(request.path_info)
  File "/usr/lib64/python3.4/site-packages/django/core/urlresolvers.py", line 365, in resolve
    for pattern in self.url_patterns:
  File "/usr/lib64/python3.4/site-packages/django/core/urlresolvers.py", line 401, in url_patterns
    patterns = getattr(self.urlconf_module, "urlpatterns", self.urlconf_module)
  File "/usr/lib64/python3.4/site-packages/django/core/urlresolvers.py", line 395, in urlconf_module
    self._urlconf_module = import_module(self.urlconf_name)
  File "/usr/lib64/python3.4/importlib/__init__.py", line 109, in import_module
    return _bootstrap._gcd_import(name[level:], package, level)
  File "<frozen importlib._bootstrap>", line 2254, in _gcd_import
  File "<frozen importlib._bootstrap>", line 2237, in _find_and_load
  File "<frozen importlib._bootstrap>", line 2226, in _find_and_load_unlocked
  File "<frozen importlib._bootstrap>", line 1200, in _load_unlocked
  File "<frozen importlib._bootstrap>", line 1129, in _exec
  File "<frozen importlib._bootstrap>", line 1467, in exec_module
  File "<frozen importlib._bootstrap>", line 1572, in get_code
  File "<frozen importlib._bootstrap>", line 1532, in source_to_code
  File "<frozen importlib._bootstrap>", line 321, in _call_with_frames_removed
  File "/root/django/first/mysite/mysite/urls.py", line 29
    url(r'newtpb/$', respond_with_tpb_quote)
      ^
SyntaxError: invalid syntax
Internal Server Error: /newtpb/
Traceback (most recent call last):
  File "/usr/lib64/python3.4/site-packages/django/core/urlresolvers.py", line 393, in urlconf_module
    return self._urlconf_module
AttributeError: 'RegexURLResolver' object has no attribute '_urlconf_module'

During handling of the above exception, another exception occurred:

Traceback (most recent call last):
  File "/usr/lib64/python3.4/site-packages/django/core/handlers/base.py", line 119, in get_response
    resolver_match = resolver.resolve(request.path_info)
  File "/usr/lib64/python3.4/site-packages/django/core/urlresolvers.py", line 365, in resolve
    for pattern in self.url_patterns:
  File "/usr/lib64/python3.4/site-packages/django/core/urlresolvers.py", line 401, in url_patterns
    patterns = getattr(self.urlconf_module, "urlpatterns", self.urlconf_module)
  File "/usr/lib64/python3.4/site-packages/django/core/urlresolvers.py", line 395, in urlconf_module
    self._urlconf_module = import_module(self.urlconf_name)
  File "/usr/lib64/python3.4/importlib/__init__.py", line 109, in import_module
    return _bootstrap._gcd_import(name[level:], package, level)
  File "<frozen importlib._bootstrap>", line 2254, in _gcd_import
  File "<frozen importlib._bootstrap>", line 2237, in _find_and_load
  File "<frozen importlib._bootstrap>", line 2226, in _find_and_load_unlocked
  File "<frozen importlib._bootstrap>", line 1200, in _load_unlocked
  File "<frozen importlib._bootstrap>", line 1129, in _exec
  File "<frozen importlib._bootstrap>", line 1467, in exec_module
  File "<frozen importlib._bootstrap>", line 1572, in get_code
  File "<frozen importlib._bootstrap>", line 1532, in source_to_code
  File "<frozen importlib._bootstrap>", line 321, in _call_with_frames_removed
  File "/root/django/first/mysite/mysite/urls.py", line 29
    url(r'newtpb/$', respond_with_tpb_quote)
      ^
SyntaxError: invalid syntax
Internal Server Error: /newtpb/
Traceback (most recent call last):
  File "/usr/lib64/python3.4/site-packages/django/core/urlresolvers.py", line 393, in urlconf_module
    return self._urlconf_module
AttributeError: 'RegexURLResolver' object has no attribute '_urlconf_module'

During handling of the above exception, another exception occurred:

Traceback (most recent call last):
  File "/usr/lib64/python3.4/site-packages/django/core/handlers/base.py", line 119, in get_response
    resolver_match = resolver.resolve(request.path_info)
  File "/usr/lib64/python3.4/site-packages/django/core/urlresolvers.py", line 365, in resolve
    for pattern in self.url_patterns:
  File "/usr/lib64/python3.4/site-packages/django/core/urlresolvers.py", line 401, in url_patterns
    patterns = getattr(self.urlconf_module, "urlpatterns", self.urlconf_module)
  File "/usr/lib64/python3.4/site-packages/django/core/urlresolvers.py", line 395, in urlconf_module
    self._urlconf_module = import_module(self.urlconf_name)
  File "/usr/lib64/python3.4/importlib/__init__.py", line 109, in import_module
    return _bootstrap._gcd_import(name[level:], package, level)
  File "<frozen importlib._bootstrap>", line 2254, in _gcd_import
  File "<frozen importlib._bootstrap>", line 2237, in _find_and_load
  File "<frozen importlib._bootstrap>", line 2226, in _find_and_load_unlocked
  File "<frozen importlib._bootstrap>", line 1200, in _load_unlocked
  File "<frozen importlib._bootstrap>", line 1129, in _exec
  File "<frozen importlib._bootstrap>", line 1467, in exec_module
  File "<frozen importlib._bootstrap>", line 1572, in get_code
  File "<frozen importlib._bootstrap>", line 1532, in source_to_code
  File "<frozen importlib._bootstrap>", line 321, in _call_with_frames_removed
  File "/root/django/first/mysite/mysite/urls.py", line 29
    url(r'newtpb/$', respond_with_tpb_quote)
      ^
SyntaxError: invalid syntax
(0.000) QUERY = "\n            SELECT name, type FROM sqlite_master\n            WHERE type in ('table', 'view') AND NOT name='sqlite_sequence'\n            ORDER BY name" - PARAMS = (); args=None
(0.000) QUERY = 'SELECT "django_migrations"."app", "django_migrations"."name" FROM "django_migrations"' - PARAMS = (); args=()
Internal Server Error: /newtpb/
Traceback (most recent call last):
  File "/usr/lib64/python3.4/site-packages/django/core/urlresolvers.py", line 393, in urlconf_module
    return self._urlconf_module
AttributeError: 'RegexURLResolver' object has no attribute '_urlconf_module'

During handling of the above exception, another exception occurred:

Traceback (most recent call last):
  File "/usr/lib64/python3.4/site-packages/django/core/handlers/base.py", line 119, in get_response
    resolver_match = resolver.resolve(request.path_info)
  File "/usr/lib64/python3.4/site-packages/django/core/urlresolvers.py", line 365, in resolve
    for pattern in self.url_patterns:
  File "/usr/lib64/python3.4/site-packages/django/core/urlresolvers.py", line 401, in url_patterns
    patterns = getattr(self.urlconf_module, "urlpatterns", self.urlconf_module)
  File "/usr/lib64/python3.4/site-packages/django/core/urlresolvers.py", line 395, in urlconf_module
    self._urlconf_module = import_module(self.urlconf_name)
  File "/usr/lib64/python3.4/importlib/__init__.py", line 109, in import_module
    return _bootstrap._gcd_import(name[level:], package, level)
  File "<frozen importlib._bootstrap>", line 2254, in _gcd_import
  File "<frozen importlib._bootstrap>", line 2237, in _find_and_load
  File "<frozen importlib._bootstrap>", line 2226, in _find_and_load_unlocked
  File "<frozen importlib._bootstrap>", line 1200, in _load_unlocked
  File "<frozen importlib._bootstrap>", line 1129, in _exec
  File "<frozen importlib._bootstrap>", line 1467, in exec_module
  File "<frozen importlib._bootstrap>", line 1572, in get_code
  File "<frozen importlib._bootstrap>", line 1532, in source_to_code
  File "<frozen importlib._bootstrap>", line 321, in _call_with_frames_removed
  File "/root/django/first/mysite/mysite/urls.py", line 33
    url(r'newtpb/$', respond_with_tpb_quote)
      ^
SyntaxError: invalid syntax
Internal Server Error: /newtpb/
Traceback (most recent call last):
  File "/usr/lib64/python3.4/site-packages/django/core/urlresolvers.py", line 393, in urlconf_module
    return self._urlconf_module
AttributeError: 'RegexURLResolver' object has no attribute '_urlconf_module'

During handling of the above exception, another exception occurred:

Traceback (most recent call last):
  File "/usr/lib64/python3.4/site-packages/django/core/handlers/base.py", line 119, in get_response
    resolver_match = resolver.resolve(request.path_info)
  File "/usr/lib64/python3.4/site-packages/django/core/urlresolvers.py", line 365, in resolve
    for pattern in self.url_patterns:
  File "/usr/lib64/python3.4/site-packages/django/core/urlresolvers.py", line 401, in url_patterns
    patterns = getattr(self.urlconf_module, "urlpatterns", self.urlconf_module)
  File "/usr/lib64/python3.4/site-packages/django/core/urlresolvers.py", line 395, in urlconf_module
    self._urlconf_module = import_module(self.urlconf_name)
  File "/usr/lib64/python3.4/importlib/__init__.py", line 109, in import_module
    return _bootstrap._gcd_import(name[level:], package, level)
  File "<frozen importlib._bootstrap>", line 2254, in _gcd_import
  File "<frozen importlib._bootstrap>", line 2237, in _find_and_load
  File "<frozen importlib._bootstrap>", line 2226, in _find_and_load_unlocked
  File "<frozen importlib._bootstrap>", line 1200, in _load_unlocked
  File "<frozen importlib._bootstrap>", line 1129, in _exec
  File "<frozen importlib._bootstrap>", line 1467, in exec_module
  File "<frozen importlib._bootstrap>", line 1572, in get_code
  File "<frozen importlib._bootstrap>", line 1532, in source_to_code
  File "<frozen importlib._bootstrap>", line 321, in _call_with_frames_removed
  File "/root/django/first/mysite/mysite/urls.py", line 33
    url(r'newtpb/$', respond_with_tpb_quote)
      ^
SyntaxError: invalid syntax
Internal Server Error: /newtpb/
Traceback (most recent call last):
  File "/usr/lib64/python3.4/site-packages/django/core/urlresolvers.py", line 393, in urlconf_module
    return self._urlconf_module
AttributeError: 'RegexURLResolver' object has no attribute '_urlconf_module'

During handling of the above exception, another exception occurred:

Traceback (most recent call last):
  File "/usr/lib64/python3.4/site-packages/django/core/handlers/base.py", line 119, in get_response
    resolver_match = resolver.resolve(request.path_info)
  File "/usr/lib64/python3.4/site-packages/django/core/urlresolvers.py", line 365, in resolve
    for pattern in self.url_patterns:
  File "/usr/lib64/python3.4/site-packages/django/core/urlresolvers.py", line 401, in url_patterns
    patterns = getattr(self.urlconf_module, "urlpatterns", self.urlconf_module)
  File "/usr/lib64/python3.4/site-packages/django/core/urlresolvers.py", line 395, in urlconf_module
    self._urlconf_module = import_module(self.urlconf_name)
  File "/usr/lib64/python3.4/importlib/__init__.py", line 109, in import_module
    return _bootstrap._gcd_import(name[level:], package, level)
  File "<frozen importlib._bootstrap>", line 2254, in _gcd_import
  File "<frozen importlib._bootstrap>", line 2237, in _find_and_load
  File "<frozen importlib._bootstrap>", line 2226, in _find_and_load_unlocked
  File "<frozen importlib._bootstrap>", line 1200, in _load_unlocked
  File "<frozen importlib._bootstrap>", line 1129, in _exec
  File "<frozen importlib._bootstrap>", line 1467, in exec_module
  File "<frozen importlib._bootstrap>", line 1572, in get_code
  File "<frozen importlib._bootstrap>", line 1532, in source_to_code
  File "<frozen importlib._bootstrap>", line 321, in _call_with_frames_removed
  File "/root/django/first/mysite/mysite/urls.py", line 33
    url(r'newtpb/$', respond_with_tpb_quote)
      ^
SyntaxError: invalid syntax
Internal Server Error: /newtpb/
Traceback (most recent call last):
  File "/usr/lib64/python3.4/site-packages/django/core/urlresolvers.py", line 393, in urlconf_module
    return self._urlconf_module
AttributeError: 'RegexURLResolver' object has no attribute '_urlconf_module'

During handling of the above exception, another exception occurred:

Traceback (most recent call last):
  File "/usr/lib64/python3.4/site-packages/django/core/handlers/base.py", line 119, in get_response
    resolver_match = resolver.resolve(request.path_info)
  File "/usr/lib64/python3.4/site-packages/django/core/urlresolvers.py", line 365, in resolve
    for pattern in self.url_patterns:
  File "/usr/lib64/python3.4/site-packages/django/core/urlresolvers.py", line 401, in url_patterns
    patterns = getattr(self.urlconf_module, "urlpatterns", self.urlconf_module)
  File "/usr/lib64/python3.4/site-packages/django/core/urlresolvers.py", line 395, in urlconf_module
    self._urlconf_module = import_module(self.urlconf_name)
  File "/usr/lib64/python3.4/importlib/__init__.py", line 109, in import_module
    return _bootstrap._gcd_import(name[level:], package, level)
  File "<frozen importlib._bootstrap>", line 2254, in _gcd_import
  File "<frozen importlib._bootstrap>", line 2237, in _find_and_load
  File "<frozen importlib._bootstrap>", line 2226, in _find_and_load_unlocked
  File "<frozen importlib._bootstrap>", line 1200, in _load_unlocked
  File "<frozen importlib._bootstrap>", line 1129, in _exec
  File "<frozen importlib._bootstrap>", line 1467, in exec_module
  File "<frozen importlib._bootstrap>", line 1572, in get_code
  File "<frozen importlib._bootstrap>", line 1532, in source_to_code
  File "<frozen importlib._bootstrap>", line 321, in _call_with_frames_removed
  File "/root/django/first/mysite/mysite/urls.py", line 33
    url(r'newtpb/$', respond_with_tpb_quote)
      ^
SyntaxError: invalid syntax
Internal Server Error: /newtpb/
Traceback (most recent call last):
  File "/usr/lib64/python3.4/site-packages/django/core/urlresolvers.py", line 393, in urlconf_module
    return self._urlconf_module
AttributeError: 'RegexURLResolver' object has no attribute '_urlconf_module'

During handling of the above exception, another exception occurred:

Traceback (most recent call last):
  File "/usr/lib64/python3.4/site-packages/django/core/handlers/base.py", line 119, in get_response
    resolver_match = resolver.resolve(request.path_info)
  File "/usr/lib64/python3.4/site-packages/django/core/urlresolvers.py", line 365, in resolve
    for pattern in self.url_patterns:
  File "/usr/lib64/python3.4/site-packages/django/core/urlresolvers.py", line 401, in url_patterns
    patterns = getattr(self.urlconf_module, "urlpatterns", self.urlconf_module)
  File "/usr/lib64/python3.4/site-packages/django/core/urlresolvers.py", line 395, in urlconf_module
    self._urlconf_module = import_module(self.urlconf_name)
  File "/usr/lib64/python3.4/importlib/__init__.py", line 109, in import_module
    return _bootstrap._gcd_import(name[level:], package, level)
  File "<frozen importlib._bootstrap>", line 2254, in _gcd_import
  File "<frozen importlib._bootstrap>", line 2237, in _find_and_load
  File "<frozen importlib._bootstrap>", line 2226, in _find_and_load_unlocked
  File "<frozen importlib._bootstrap>", line 1200, in _load_unlocked
  File "<frozen importlib._bootstrap>", line 1129, in _exec
  File "<frozen importlib._bootstrap>", line 1467, in exec_module
  File "<frozen importlib._bootstrap>", line 1572, in get_code
  File "<frozen importlib._bootstrap>", line 1532, in source_to_code
  File "<frozen importlib._bootstrap>", line 321, in _call_with_frames_removed
  File "/root/django/first/mysite/mysite/urls.py", line 33
    url(r'newtpb/$', respond_with_tpb_quote)
      ^
SyntaxError: invalid syntax
(0.000) QUERY = "\n            SELECT name, type FROM sqlite_master\n            WHERE type in ('table', 'view') AND NOT name='sqlite_sequence'\n            ORDER BY name" - PARAMS = (); args=None
(0.008) QUERY = 'SELECT "django_migrations"."app", "django_migrations"."name" FROM "django_migrations"' - PARAMS = (); args=()
Internal Server Error: /newtpb/
Traceback (most recent call last):
  File "/usr/lib64/python3.4/site-packages/django/core/urlresolvers.py", line 393, in urlconf_module
    return self._urlconf_module
AttributeError: 'RegexURLResolver' object has no attribute '_urlconf_module'

During handling of the above exception, another exception occurred:

Traceback (most recent call last):
  File "/usr/lib64/python3.4/site-packages/django/core/handlers/base.py", line 119, in get_response
    resolver_match = resolver.resolve(request.path_info)
  File "/usr/lib64/python3.4/site-packages/django/core/urlresolvers.py", line 365, in resolve
    for pattern in self.url_patterns:
  File "/usr/lib64/python3.4/site-packages/django/core/urlresolvers.py", line 401, in url_patterns
    patterns = getattr(self.urlconf_module, "urlpatterns", self.urlconf_module)
  File "/usr/lib64/python3.4/site-packages/django/core/urlresolvers.py", line 395, in urlconf_module
    self._urlconf_module = import_module(self.urlconf_name)
  File "/usr/lib64/python3.4/importlib/__init__.py", line 109, in import_module
    return _bootstrap._gcd_import(name[level:], package, level)
  File "<frozen importlib._bootstrap>", line 2254, in _gcd_import
  File "<frozen importlib._bootstrap>", line 2237, in _find_and_load
  File "<frozen importlib._bootstrap>", line 2226, in _find_and_load_unlocked
  File "<frozen importlib._bootstrap>", line 1200, in _load_unlocked
  File "<frozen importlib._bootstrap>", line 1129, in _exec
  File "<frozen importlib._bootstrap>", line 1467, in exec_module
  File "<frozen importlib._bootstrap>", line 1572, in get_code
  File "<frozen importlib._bootstrap>", line 1532, in source_to_code
  File "<frozen importlib._bootstrap>", line 321, in _call_with_frames_removed
  File "/root/django/first/mysite/mysite/urls.py", line 33
    url(r'newtpb/$', respond_with_tpb_quote)
      ^
SyntaxError: invalid syntax
Internal Server Error: /newtpb/
Traceback (most recent call last):
  File "/usr/lib64/python3.4/site-packages/django/core/urlresolvers.py", line 393, in urlconf_module
    return self._urlconf_module
AttributeError: 'RegexURLResolver' object has no attribute '_urlconf_module'

During handling of the above exception, another exception occurred:

Traceback (most recent call last):
  File "/usr/lib64/python3.4/site-packages/django/core/handlers/base.py", line 119, in get_response
    resolver_match = resolver.resolve(request.path_info)
  File "/usr/lib64/python3.4/site-packages/django/core/urlresolvers.py", line 365, in resolve
    for pattern in self.url_patterns:
  File "/usr/lib64/python3.4/site-packages/django/core/urlresolvers.py", line 401, in url_patterns
    patterns = getattr(self.urlconf_module, "urlpatterns", self.urlconf_module)
  File "/usr/lib64/python3.4/site-packages/django/core/urlresolvers.py", line 395, in urlconf_module
    self._urlconf_module = import_module(self.urlconf_name)
  File "/usr/lib64/python3.4/importlib/__init__.py", line 109, in import_module
    return _bootstrap._gcd_import(name[level:], package, level)
  File "<frozen importlib._bootstrap>", line 2254, in _gcd_import
  File "<frozen importlib._bootstrap>", line 2237, in _find_and_load
  File "<frozen importlib._bootstrap>", line 2226, in _find_and_load_unlocked
  File "<frozen importlib._bootstrap>", line 1200, in _load_unlocked
  File "<frozen importlib._bootstrap>", line 1129, in _exec
  File "<frozen importlib._bootstrap>", line 1467, in exec_module
  File "<frozen importlib._bootstrap>", line 1572, in get_code
  File "<frozen importlib._bootstrap>", line 1532, in source_to_code
  File "<frozen importlib._bootstrap>", line 321, in _call_with_frames_removed
  File "/root/django/first/mysite/mysite/urls.py", line 33
    url(r'newtpb/$', respond_with_tpb_quote)
      ^
SyntaxError: invalid syntax
Internal Server Error: /newtpb/
Traceback (most recent call last):
  File "/usr/lib64/python3.4/site-packages/django/core/urlresolvers.py", line 393, in urlconf_module
    return self._urlconf_module
AttributeError: 'RegexURLResolver' object has no attribute '_urlconf_module'

During handling of the above exception, another exception occurred:

Traceback (most recent call last):
  File "/usr/lib64/python3.4/site-packages/django/core/handlers/base.py", line 119, in get_response
    resolver_match = resolver.resolve(request.path_info)
  File "/usr/lib64/python3.4/site-packages/django/core/urlresolvers.py", line 365, in resolve
    for pattern in self.url_patterns:
  File "/usr/lib64/python3.4/site-packages/django/core/urlresolvers.py", line 401, in url_patterns
    patterns = getattr(self.urlconf_module, "urlpatterns", self.urlconf_module)
  File "/usr/lib64/python3.4/site-packages/django/core/urlresolvers.py", line 395, in urlconf_module
    self._urlconf_module = import_module(self.urlconf_name)
  File "/usr/lib64/python3.4/importlib/__init__.py", line 109, in import_module
    return _bootstrap._gcd_import(name[level:], package, level)
  File "<frozen importlib._bootstrap>", line 2254, in _gcd_import
  File "<frozen importlib._bootstrap>", line 2237, in _find_and_load
  File "<frozen importlib._bootstrap>", line 2226, in _find_and_load_unlocked
  File "<frozen importlib._bootstrap>", line 1200, in _load_unlocked
  File "<frozen importlib._bootstrap>", line 1129, in _exec
  File "<frozen importlib._bootstrap>", line 1467, in exec_module
  File "<frozen importlib._bootstrap>", line 1572, in get_code
  File "<frozen importlib._bootstrap>", line 1532, in source_to_code
  File "<frozen importlib._bootstrap>", line 321, in _call_with_frames_removed
  File "/root/django/first/mysite/mysite/urls.py", line 33
    url(r'newtpb/$', respond_with_tpb_quote)
      ^
SyntaxError: invalid syntax
Internal Server Error: /newtpb/
Traceback (most recent call last):
  File "/usr/lib64/python3.4/site-packages/django/core/urlresolvers.py", line 393, in urlconf_module
    return self._urlconf_module
AttributeError: 'RegexURLResolver' object has no attribute '_urlconf_module'

During handling of the above exception, another exception occurred:

Traceback (most recent call last):
  File "/usr/lib64/python3.4/site-packages/django/core/handlers/base.py", line 119, in get_response
    resolver_match = resolver.resolve(request.path_info)
  File "/usr/lib64/python3.4/site-packages/django/core/urlresolvers.py", line 365, in resolve
    for pattern in self.url_patterns:
  File "/usr/lib64/python3.4/site-packages/django/core/urlresolvers.py", line 401, in url_patterns
    patterns = getattr(self.urlconf_module, "urlpatterns", self.urlconf_module)
  File "/usr/lib64/python3.4/site-packages/django/core/urlresolvers.py", line 395, in urlconf_module
    self._urlconf_module = import_module(self.urlconf_name)
  File "/usr/lib64/python3.4/importlib/__init__.py", line 109, in import_module
    return _bootstrap._gcd_import(name[level:], package, level)
  File "<frozen importlib._bootstrap>", line 2254, in _gcd_import
  File "<frozen importlib._bootstrap>", line 2237, in _find_and_load
  File "<frozen importlib._bootstrap>", line 2226, in _find_and_load_unlocked
  File "<frozen importlib._bootstrap>", line 1200, in _load_unlocked
  File "<frozen importlib._bootstrap>", line 1129, in _exec
  File "<frozen importlib._bootstrap>", line 1467, in exec_module
  File "<frozen importlib._bootstrap>", line 1572, in get_code
  File "<frozen importlib._bootstrap>", line 1532, in source_to_code
  File "<frozen importlib._bootstrap>", line 321, in _call_with_frames_removed
  File "/root/django/first/mysite/mysite/urls.py", line 33
    url(r'newtpb/$', respond_with_tpb_quote)
      ^
SyntaxError: invalid syntax
Internal Server Error: /newtpb/
Traceback (most recent call last):
  File "/usr/lib64/python3.4/site-packages/django/core/urlresolvers.py", line 393, in urlconf_module
    return self._urlconf_module
AttributeError: 'RegexURLResolver' object has no attribute '_urlconf_module'

During handling of the above exception, another exception occurred:

Traceback (most recent call last):
  File "/usr/lib64/python3.4/site-packages/django/core/handlers/base.py", line 119, in get_response
    resolver_match = resolver.resolve(request.path_info)
  File "/usr/lib64/python3.4/site-packages/django/core/urlresolvers.py", line 365, in resolve
    for pattern in self.url_patterns:
  File "/usr/lib64/python3.4/site-packages/django/core/urlresolvers.py", line 401, in url_patterns
    patterns = getattr(self.urlconf_module, "urlpatterns", self.urlconf_module)
  File "/usr/lib64/python3.4/site-packages/django/core/urlresolvers.py", line 395, in urlconf_module
    self._urlconf_module = import_module(self.urlconf_name)
  File "/usr/lib64/python3.4/importlib/__init__.py", line 109, in import_module
    return _bootstrap._gcd_import(name[level:], package, level)
  File "<frozen importlib._bootstrap>", line 2254, in _gcd_import
  File "<frozen importlib._bootstrap>", line 2237, in _find_and_load
  File "<frozen importlib._bootstrap>", line 2226, in _find_and_load_unlocked
  File "<frozen importlib._bootstrap>", line 1200, in _load_unlocked
  File "<frozen importlib._bootstrap>", line 1129, in _exec
  File "<frozen importlib._bootstrap>", line 1467, in exec_module
  File "<frozen importlib._bootstrap>", line 1572, in get_code
  File "<frozen importlib._bootstrap>", line 1532, in source_to_code
  File "<frozen importlib._bootstrap>", line 321, in _call_with_frames_removed
  File "/root/django/first/mysite/mysite/urls.py", line 33
    url(r'newtpb/$', respond_with_tpb_quote)
      ^
SyntaxError: invalid syntax
Internal Server Error: /newtpb/
Traceback (most recent call last):
  File "/usr/lib64/python3.4/site-packages/django/core/urlresolvers.py", line 393, in urlconf_module
    return self._urlconf_module
AttributeError: 'RegexURLResolver' object has no attribute '_urlconf_module'

During handling of the above exception, another exception occurred:

Traceback (most recent call last):
  File "/usr/lib64/python3.4/site-packages/django/core/handlers/base.py", line 119, in get_response
    resolver_match = resolver.resolve(request.path_info)
  File "/usr/lib64/python3.4/site-packages/django/core/urlresolvers.py", line 365, in resolve
    for pattern in self.url_patterns:
  File "/usr/lib64/python3.4/site-packages/django/core/urlresolvers.py", line 401, in url_patterns
    patterns = getattr(self.urlconf_module, "urlpatterns", self.urlconf_module)
  File "/usr/lib64/python3.4/site-packages/django/core/urlresolvers.py", line 395, in urlconf_module
    self._urlconf_module = import_module(self.urlconf_name)
  File "/usr/lib64/python3.4/importlib/__init__.py", line 109, in import_module
    return _bootstrap._gcd_import(name[level:], package, level)
  File "<frozen importlib._bootstrap>", line 2254, in _gcd_import
  File "<frozen importlib._bootstrap>", line 2237, in _find_and_load
  File "<frozen importlib._bootstrap>", line 2226, in _find_and_load_unlocked
  File "<frozen importlib._bootstrap>", line 1200, in _load_unlocked
  File "<frozen importlib._bootstrap>", line 1129, in _exec
  File "<frozen importlib._bootstrap>", line 1467, in exec_module
  File "<frozen importlib._bootstrap>", line 1572, in get_code
  File "<frozen importlib._bootstrap>", line 1532, in source_to_code
  File "<frozen importlib._bootstrap>", line 321, in _call_with_frames_removed
  File "/root/django/first/mysite/mysite/urls.py", line 33
    url(r'newtpb/$', respond_with_tpb_quote)
      ^
SyntaxError: invalid syntax
Internal Server Error: /newtpb/
Traceback (most recent call last):
  File "/usr/lib64/python3.4/site-packages/django/core/urlresolvers.py", line 393, in urlconf_module
    return self._urlconf_module
AttributeError: 'RegexURLResolver' object has no attribute '_urlconf_module'

During handling of the above exception, another exception occurred:

Traceback (most recent call last):
  File "/usr/lib64/python3.4/site-packages/django/core/handlers/base.py", line 119, in get_response
    resolver_match = resolver.resolve(request.path_info)
  File "/usr/lib64/python3.4/site-packages/django/core/urlresolvers.py", line 365, in resolve
    for pattern in self.url_patterns:
  File "/usr/lib64/python3.4/site-packages/django/core/urlresolvers.py", line 401, in url_patterns
    patterns = getattr(self.urlconf_module, "urlpatterns", self.urlconf_module)
  File "/usr/lib64/python3.4/site-packages/django/core/urlresolvers.py", line 395, in urlconf_module
    self._urlconf_module = import_module(self.urlconf_name)
  File "/usr/lib64/python3.4/importlib/__init__.py", line 109, in import_module
    return _bootstrap._gcd_import(name[level:], package, level)
  File "<frozen importlib._bootstrap>", line 2254, in _gcd_import
  File "<frozen importlib._bootstrap>", line 2237, in _find_and_load
  File "<frozen importlib._bootstrap>", line 2226, in _find_and_load_unlocked
  File "<frozen importlib._bootstrap>", line 1200, in _load_unlocked
  File "<frozen importlib._bootstrap>", line 1129, in _exec
  File "<frozen importlib._bootstrap>", line 1467, in exec_module
  File "<frozen importlib._bootstrap>", line 1572, in get_code
  File "<frozen importlib._bootstrap>", line 1532, in source_to_code
  File "<frozen importlib._bootstrap>", line 321, in _call_with_frames_removed
  File "/root/django/first/mysite/mysite/urls.py", line 33
    url(r'newtpb/$', respond_with_tpb_quote)
      ^
SyntaxError: invalid syntax
(0.000) QUERY = "\n            SELECT name, type FROM sqlite_master\n            WHERE type in ('table', 'view') AND NOT name='sqlite_sequence'\n            ORDER BY name" - PARAMS = (); args=None
(0.000) QUERY = 'SELECT "django_migrations"."app", "django_migrations"."name" FROM "django_migrations"' - PARAMS = (); args=()
Internal Server Error: /newtpb/
Traceback (most recent call last):
  File "/usr/lib64/python3.4/site-packages/django/core/urlresolvers.py", line 393, in urlconf_module
    return self._urlconf_module
AttributeError: 'RegexURLResolver' object has no attribute '_urlconf_module'

During handling of the above exception, another exception occurred:

Traceback (most recent call last):
  File "/usr/lib64/python3.4/site-packages/django/core/handlers/base.py", line 119, in get_response
    resolver_match = resolver.resolve(request.path_info)
  File "/usr/lib64/python3.4/site-packages/django/core/urlresolvers.py", line 365, in resolve
    for pattern in self.url_patterns:
  File "/usr/lib64/python3.4/site-packages/django/core/urlresolvers.py", line 401, in url_patterns
    patterns = getattr(self.urlconf_module, "urlpatterns", self.urlconf_module)
  File "/usr/lib64/python3.4/site-packages/django/core/urlresolvers.py", line 395, in urlconf_module
    self._urlconf_module = import_module(self.urlconf_name)
  File "/usr/lib64/python3.4/importlib/__init__.py", line 109, in import_module
    return _bootstrap._gcd_import(name[level:], package, level)
  File "<frozen importlib._bootstrap>", line 2254, in _gcd_import
  File "<frozen importlib._bootstrap>", line 2237, in _find_and_load
  File "<frozen importlib._bootstrap>", line 2226, in _find_and_load_unlocked
  File "<frozen importlib._bootstrap>", line 1200, in _load_unlocked
  File "<frozen importlib._bootstrap>", line 1129, in _exec
  File "<frozen importlib._bootstrap>", line 1467, in exec_module
  File "<frozen importlib._bootstrap>", line 1572, in get_code
  File "<frozen importlib._bootstrap>", line 1532, in source_to_code
  File "<frozen importlib._bootstrap>", line 321, in _call_with_frames_removed
  File "/root/django/first/mysite/mysite/urls.py", line 34
    url(r'newtpb/$', respond_with_tpb_quote)
      ^
SyntaxError: invalid syntax
Internal Server Error: /newtpb/
Traceback (most recent call last):
  File "/usr/lib64/python3.4/site-packages/django/core/urlresolvers.py", line 393, in urlconf_module
    return self._urlconf_module
AttributeError: 'RegexURLResolver' object has no attribute '_urlconf_module'

During handling of the above exception, another exception occurred:

Traceback (most recent call last):
  File "/usr/lib64/python3.4/site-packages/django/core/handlers/base.py", line 119, in get_response
    resolver_match = resolver.resolve(request.path_info)
  File "/usr/lib64/python3.4/site-packages/django/core/urlresolvers.py", line 365, in resolve
    for pattern in self.url_patterns:
  File "/usr/lib64/python3.4/site-packages/django/core/urlresolvers.py", line 401, in url_patterns
    patterns = getattr(self.urlconf_module, "urlpatterns", self.urlconf_module)
  File "/usr/lib64/python3.4/site-packages/django/core/urlresolvers.py", line 395, in urlconf_module
    self._urlconf_module = import_module(self.urlconf_name)
  File "/usr/lib64/python3.4/importlib/__init__.py", line 109, in import_module
    return _bootstrap._gcd_import(name[level:], package, level)
  File "<frozen importlib._bootstrap>", line 2254, in _gcd_import
  File "<frozen importlib._bootstrap>", line 2237, in _find_and_load
  File "<frozen importlib._bootstrap>", line 2226, in _find_and_load_unlocked
  File "<frozen importlib._bootstrap>", line 1200, in _load_unlocked
  File "<frozen importlib._bootstrap>", line 1129, in _exec
  File "<frozen importlib._bootstrap>", line 1467, in exec_module
  File "<frozen importlib._bootstrap>", line 1572, in get_code
  File "<frozen importlib._bootstrap>", line 1532, in source_to_code
  File "<frozen importlib._bootstrap>", line 321, in _call_with_frames_removed
  File "/root/django/first/mysite/mysite/urls.py", line 34
    url(r'newtpb/$', respond_with_tpb_quote)
      ^
SyntaxError: invalid syntax
Internal Server Error: /newtpb/
Traceback (most recent call last):
  File "/usr/lib64/python3.4/site-packages/django/core/urlresolvers.py", line 393, in urlconf_module
    return self._urlconf_module
AttributeError: 'RegexURLResolver' object has no attribute '_urlconf_module'

During handling of the above exception, another exception occurred:

Traceback (most recent call last):
  File "/usr/lib64/python3.4/site-packages/django/core/handlers/base.py", line 119, in get_response
    resolver_match = resolver.resolve(request.path_info)
  File "/usr/lib64/python3.4/site-packages/django/core/urlresolvers.py", line 365, in resolve
    for pattern in self.url_patterns:
  File "/usr/lib64/python3.4/site-packages/django/core/urlresolvers.py", line 401, in url_patterns
    patterns = getattr(self.urlconf_module, "urlpatterns", self.urlconf_module)
  File "/usr/lib64/python3.4/site-packages/django/core/urlresolvers.py", line 395, in urlconf_module
    self._urlconf_module = import_module(self.urlconf_name)
  File "/usr/lib64/python3.4/importlib/__init__.py", line 109, in import_module
    return _bootstrap._gcd_import(name[level:], package, level)
  File "<frozen importlib._bootstrap>", line 2254, in _gcd_import
  File "<frozen importlib._bootstrap>", line 2237, in _find_and_load
  File "<frozen importlib._bootstrap>", line 2226, in _find_and_load_unlocked
  File "<frozen importlib._bootstrap>", line 1200, in _load_unlocked
  File "<frozen importlib._bootstrap>", line 1129, in _exec
  File "<frozen importlib._bootstrap>", line 1467, in exec_module
  File "<frozen importlib._bootstrap>", line 1572, in get_code
  File "<frozen importlib._bootstrap>", line 1532, in source_to_code
  File "<frozen importlib._bootstrap>", line 321, in _call_with_frames_removed
  File "/root/django/first/mysite/mysite/urls.py", line 34
    url(r'newtpb/$', respond_with_tpb_quote)
      ^
SyntaxError: invalid syntax
(0.001) QUERY = "\n            SELECT name, type FROM sqlite_master\n            WHERE type in ('table', 'view') AND NOT name='sqlite_sequence'\n            ORDER BY name" - PARAMS = (); args=None
(0.000) QUERY = 'SELECT "django_migrations"."app", "django_migrations"."name" FROM "django_migrations"' - PARAMS = (); args=()
Internal Server Error: /newtpb/
Traceback (most recent call last):
  File "/usr/lib64/python3.4/site-packages/django/core/handlers/base.py", line 132, in get_response
    response = wrapped_callback(request, *callback_args, **callback_kwargs)
  File "/root/django/first/mysite/mysite/views.py", line 35, in respond_with_tpb_quote
    if(len(quotes) == 0):
UnboundLocalError: local variable 'quotes' referenced before assignment
Internal Server Error: /newtpb/
Traceback (most recent call last):
  File "/usr/lib64/python3.4/site-packages/django/core/handlers/base.py", line 132, in get_response
    response = wrapped_callback(request, *callback_args, **callback_kwargs)
  File "/root/django/first/mysite/mysite/views.py", line 35, in respond_with_tpb_quote
    if(len(quotes) == 0):
UnboundLocalError: local variable 'quotes' referenced before assignment
Internal Server Error: /newtpb/
Traceback (most recent call last):
  File "/usr/lib64/python3.4/site-packages/django/core/handlers/base.py", line 132, in get_response
    response = wrapped_callback(request, *callback_args, **callback_kwargs)
  File "/root/django/first/mysite/mysite/views.py", line 35, in respond_with_tpb_quote
    if(len(quotes) == 0):
UnboundLocalError: local variable 'quotes' referenced before assignment
Internal Server Error: /newtpb/
Traceback (most recent call last):
  File "/usr/lib64/python3.4/site-packages/django/core/handlers/base.py", line 132, in get_response
    response = wrapped_callback(request, *callback_args, **callback_kwargs)
  File "/root/django/first/mysite/mysite/views.py", line 35, in respond_with_tpb_quote
    if(len(quotes) == 0):
UnboundLocalError: local variable 'quotes' referenced before assignment
Internal Server Error: /newtpb/
Traceback (most recent call last):
  File "/usr/lib64/python3.4/site-packages/django/core/handlers/base.py", line 132, in get_response
    response = wrapped_callback(request, *callback_args, **callback_kwargs)
  File "/root/django/first/mysite/mysite/views.py", line 35, in respond_with_tpb_quote
    if(len(quotes) == 0):
UnboundLocalError: local variable 'quotes' referenced before assignment
Internal Server Error: /newtpb/
Traceback (most recent call last):
  File "/usr/lib64/python3.4/site-packages/django/core/handlers/base.py", line 132, in get_response
    response = wrapped_callback(request, *callback_args, **callback_kwargs)
  File "/root/django/first/mysite/mysite/views.py", line 35, in respond_with_tpb_quote
    if(len(quotes) == 0):
UnboundLocalError: local variable 'quotes' referenced before assignment
(0.000) QUERY = "\n            SELECT name, type FROM sqlite_master\n            WHERE type in ('table', 'view') AND NOT name='sqlite_sequence'\n            ORDER BY name" - PARAMS = (); args=None
(0.000) QUERY = 'SELECT "django_migrations"."app", "django_migrations"."name" FROM "django_migrations"' - PARAMS = (); args=()
Not Found: /favicon.ico
Not Found: /favicon.ico
Internal Server Error: /newtpb/
Traceback (most recent call last):
  File "/usr/lib64/python3.4/site-packages/django/core/handlers/base.py", line 132, in get_response
    response = wrapped_callback(request, *callback_args, **callback_kwargs)
  File "/root/django/first/mysite/mysite/views.py", line 40, in respond_with_tpb_quote
    return JsonResponse({'quote': quotes[randy][0], 'author': quotes[randy][1]})
IndexError: list index out of range
(0.000) QUERY = "\n            SELECT name, type FROM sqlite_master\n            WHERE type in ('table', 'view') AND NOT name='sqlite_sequence'\n            ORDER BY name" - PARAMS = (); args=None
(0.000) QUERY = 'SELECT "django_migrations"."app", "django_migrations"."name" FROM "django_migrations"' - PARAMS = (); args=()
(0.015) QUERY = "\n            SELECT name, type FROM sqlite_master\n            WHERE type in ('table', 'view') AND NOT name='sqlite_sequence'\n            ORDER BY name" - PARAMS = (); args=None
(0.000) QUERY = 'SELECT "django_migrations"."app", "django_migrations"."name" FROM "django_migrations"' - PARAMS = (); args=()
Not Found: /favicon.ico
(0.000) QUERY = "\n            SELECT name, type FROM sqlite_master\n            WHERE type in ('table', 'view') AND NOT name='sqlite_sequence'\n            ORDER BY name" - PARAMS = (); args=None
(0.000) QUERY = 'SELECT "django_migrations"."app", "django_migrations"."name" FROM "django_migrations"' - PARAMS = (); args=()
(0.000) QUERY = "\n            SELECT name, type FROM sqlite_master\n            WHERE type in ('table', 'view') AND NOT name='sqlite_sequence'\n            ORDER BY name" - PARAMS = (); args=None
(0.000) QUERY = 'SELECT "django_migrations"."app", "django_migrations"."name" FROM "django_migrations"' - PARAMS = (); args=()
(0.000) QUERY = "\n            SELECT name, type FROM sqlite_master\n            WHERE type in ('table', 'view') AND NOT name='sqlite_sequence'\n            ORDER BY name" - PARAMS = (); args=None
(0.000) QUERY = 'SELECT "django_migrations"."app", "django_migrations"."name" FROM "django_migrations"' - PARAMS = (); args=()
(0.000) QUERY = "\n            SELECT name, type FROM sqlite_master\n            WHERE type in ('table', 'view') AND NOT name='sqlite_sequence'\n            ORDER BY name" - PARAMS = (); args=None
(0.000) QUERY = 'SELECT "django_migrations"."app", "django_migrations"."name" FROM "django_migrations"' - PARAMS = (); args=()
(0.000) QUERY = "\n            SELECT name, type FROM sqlite_master\n            WHERE type in ('table', 'view') AND NOT name='sqlite_sequence'\n            ORDER BY name" - PARAMS = (); args=None
(0.000) QUERY = 'SELECT "django_migrations"."app", "django_migrations"."name" FROM "django_migrations"' - PARAMS = (); args=()
(0.000) QUERY = "\n            SELECT name, type FROM sqlite_master\n            WHERE type in ('table', 'view') AND NOT name='sqlite_sequence'\n            ORDER BY name" - PARAMS = (); args=None
(0.000) QUERY = 'SELECT "django_migrations"."app", "django_migrations"."name" FROM "django_migrations"' - PARAMS = (); args=()
